Watching for file changes with StatReloader
Watching for file changes with StatReloader
"GET /admin HTTP/1.1" 301 0
"GET /admin/ HTTP/1.1" 302 0
"GET /admin/login/?next=/admin/ HTTP/1.1" 200 4170
"GET /static/admin/css/dark_mode.css HTTP/1.1" 200 2808
"GET /static/admin/css/base.css HTTP/1.1" 200 22120
"GET /static/admin/css/nav_sidebar.css HTTP/1.1" 200 2810
"GET /static/admin/css/login.css HTTP/1.1" 200 951
"GET /static/admin/css/responsive.css HTTP/1.1" 200 16565
"GET /static/admin/js/theme.js HTTP/1.1" 200 1653
"GET /static/admin/js/nav_sidebar.js HTTP/1.1" 200 3063
Not Found: /favicon.ico
"GET /favicon.ico HTTP/1.1" 404 3471
"POST /admin/login/?next=/admin/ HTTP/1.1" 302 0
"GET /admin/ HTTP/1.1" 200 10214
"GET /static/admin/css/dashboard.css HTTP/1.1" 200 441
"GET /static/admin/img/icon-addlink.svg HTTP/1.1" 200 331
"GET /static/admin/img/icon-changelink.svg HTTP/1.1" 200 380
Forbidden (CSRF token from POST incorrect.): /admin/login/
"POST /admin/login/?next=/admin/ HTTP/1.1" 403 2503
"GET /admin/login/?next=/admin/ HTTP/1.1" 302 0
"GET /admin/ HTTP/1.1" 200 10214
"POST /api/auth/anonymous/ HTTP/1.1" 201 944
"OPTIONS /api/auth/anonymous/ HTTP/1.1" 200 0
Unauthorized: /api/auth/anonymous/
"POST /api/auth/anonymous/ HTTP/1.1" 401 172
"OPTIONS /api/auth/token/refresh/ HTTP/1.1" 200 0
Unauthorized: /api/auth/token/refresh/
"POST /api/auth/token/refresh/ HTTP/1.1" 401 54
Internal Server Error: /api/auth/anonymous/
Traceback (most recent call last):
  File "C:\Users\ansh0\Desktop\Python\MindSpace\backend\venv\Lib\site-packages\django\db\backends\utils.py", line 105, in _execute
    return self.cursor.execute(sql, params)
           ^^^^^^^^^^^^^^^^^^^^^^^^^^^^^^^^
psycopg2.errors.UniqueViolation: duplicate key value violates unique constraint "accounts_user_email_key"
DETAIL:  Key (email)=() already exists.


The above exception was the direct cause of the following exception:

Traceback (most recent call last):
  File "C:\Users\ansh0\Desktop\Python\MindSpace\backend\venv\Lib\site-packages\django\core\handlers\exception.py", line 55, in inner
    response = get_response(request)
               ^^^^^^^^^^^^^^^^^^^^^
  File "C:\Users\ansh0\Desktop\Python\MindSpace\backend\venv\Lib\site-packages\django\core\handlers\base.py", line 197, in _get_response
    response = wrapped_callback(request, *callback_args, **callback_kwargs)
               ^^^^^^^^^^^^^^^^^^^^^^^^^^^^^^^^^^^^^^^^^^^^^^^^^^^^^^^^^^^^
  File "C:\Users\ansh0\Desktop\Python\MindSpace\backend\venv\Lib\site-packages\django\views\decorators\csrf.py", line 65, in _view_wrapper
    return view_func(request, *args, **kwargs)
           ^^^^^^^^^^^^^^^^^^^^^^^^^^^^^^^^^^^
  File "C:\Users\ansh0\Desktop\Python\MindSpace\backend\venv\Lib\site-packages\django\views\generic\base.py", line 105, in view
    return self.dispatch(request, *args, **kwargs)
           ^^^^^^^^^^^^^^^^^^^^^^^^^^^^^^^^^^^^^^^
  File "C:\Users\ansh0\Desktop\Python\MindSpace\backend\venv\Lib\site-packages\rest_framework\views.py", line 515, in dispatch
    response = self.handle_exception(exc)
               ^^^^^^^^^^^^^^^^^^^^^^^^^^
  File "C:\Users\ansh0\Desktop\Python\MindSpace\backend\venv\Lib\site-packages\rest_framework\views.py", line 475, in handle_exception
    self.raise_uncaught_exception(exc)
  File "C:\Users\ansh0\Desktop\Python\MindSpace\backend\venv\Lib\site-packages\rest_framework\views.py", line 486, in raise_uncaught_exception
    raise exc
  File "C:\Users\ansh0\Desktop\Python\MindSpace\backend\venv\Lib\site-packages\rest_framework\views.py", line 512, in dispatch
    response = handler(request, *args, **kwargs)
               ^^^^^^^^^^^^^^^^^^^^^^^^^^^^^^^^^
  File "C:\Users\ansh0\Desktop\Python\MindSpace\backend\venv\Lib\site-packages\rest_framework\decorators.py", line 50, in handler
    return func(*args, **kwargs)
           ^^^^^^^^^^^^^^^^^^^^^
  File "C:\Users\ansh0\Desktop\Python\MindSpace\backend\accounts\views.py", line 56, in create_anonymous_user
    user = serializer.save()
           ^^^^^^^^^^^^^^^^^
  File "C:\Users\ansh0\Desktop\Python\MindSpace\backend\venv\Lib\site-packages\rest_framework\serializers.py", line 210, in save
    self.instance = self.create(validated_data)
                    ^^^^^^^^^^^^^^^^^^^^^^^^^^^
  File "C:\Users\ansh0\Desktop\Python\MindSpace\backend\accounts\serializers.py", line 94, in create
    user = User.objects.create_user(
           ^^^^^^^^^^^^^^^^^^^^^^^^^
  File "C:\Users\ansh0\Desktop\Python\MindSpace\backend\venv\Lib\site-packages\django\contrib\auth\models.py", line 175, in create_user
    return self._create_user(username, email, password, **extra_fields)
           ^^^^^^^^^^^^^^^^^^^^^^^^^^^^^^^^^^^^^^^^^^^^^^^^^^^^^^^^^^^^
  File "C:\Users\ansh0\Desktop\Python\MindSpace\backend\venv\Lib\site-packages\django\contrib\auth\models.py", line 163, in _create_user
    user.save(using=self._db)
  File "C:\Users\ansh0\Desktop\Python\MindSpace\backend\accounts\models.py", line 65, in save
    super().save(*args, **kwargs)
  File "C:\Users\ansh0\Desktop\Python\MindSpace\backend\venv\Lib\site-packages\django\contrib\auth\base_user.py", line 65, in save
    super().save(*args, **kwargs)
  File "C:\Users\ansh0\Desktop\Python\MindSpace\backend\venv\Lib\site-packages\django\db\models\base.py", line 902, in save
    self.save_base(
  File "C:\Users\ansh0\Desktop\Python\MindSpace\backend\venv\Lib\site-packages\django\db\models\base.py", line 1008, in save_base
    updated = self._save_table(
              ^^^^^^^^^^^^^^^^^
  File "C:\Users\ansh0\Desktop\Python\MindSpace\backend\venv\Lib\site-packages\django\db\models\base.py", line 1169, in _save_table
    results = self._do_insert(
              ^^^^^^^^^^^^^^^^
  File "C:\Users\ansh0\Desktop\Python\MindSpace\backend\venv\Lib\site-packages\django\db\models\base.py", line 1210, in _do_insert
    return manager._insert(
           ^^^^^^^^^^^^^^^^
  File "C:\Users\ansh0\Desktop\Python\MindSpace\backend\venv\Lib\site-packages\django\db\models\manager.py", line 87, in manager_method
    return getattr(self.get_queryset(), name)(*args, **kwargs)
           ^^^^^^^^^^^^^^^^^^^^^^^^^^^^^^^^^^^^^^^^^^^^^^^^^^^
  File "C:\Users\ansh0\Desktop\Python\MindSpace\backend\venv\Lib\site-packages\django\db\models\query.py", line 1868, in _insert
    return query.get_compiler(using=using).execute_sql(returning_fields)
           ^^^^^^^^^^^^^^^^^^^^^^^^^^^^^^^^^^^^^^^^^^^^^^^^^^^^^^^^^^^^^
  File "C:\Users\ansh0\Desktop\Python\MindSpace\backend\venv\Lib\site-packages\django\db\models\sql\compiler.py", line 1882, in execute_sql
    cursor.execute(sql, params)
  File "C:\Users\ansh0\Desktop\Python\MindSpace\backend\venv\Lib\site-packages\django\db\backends\utils.py", line 122, in execute
    return super().execute(sql, params)
           ^^^^^^^^^^^^^^^^^^^^^^^^^^^^
  File "C:\Users\ansh0\Desktop\Python\MindSpace\backend\venv\Lib\site-packages\django\db\backends\utils.py", line 79, in execute
    return self._execute_with_wrappers(
           ^^^^^^^^^^^^^^^^^^^^^^^^^^^^
  File "C:\Users\ansh0\Desktop\Python\MindSpace\backend\venv\Lib\site-packages\django\db\backends\utils.py", line 92, in _execute_with_wrappers
    return executor(sql, params, many, context)
           ^^^^^^^^^^^^^^^^^^^^^^^^^^^^^^^^^^^^
  File "C:\Users\ansh0\Desktop\Python\MindSpace\backend\venv\Lib\site-packages\django\db\backends\utils.py", line 100, in _execute
    with self.db.wrap_database_errors:
  File "C:\Users\ansh0\Desktop\Python\MindSpace\backend\venv\Lib\site-packages\django\db\utils.py", line 91, in __exit__
    raise dj_exc_value.with_traceback(traceback) from exc_value
  File "C:\Users\ansh0\Desktop\Python\MindSpace\backend\venv\Lib\site-packages\django\db\backends\utils.py", line 105, in _execute
    return self.cursor.execute(sql, params)
           ^^^^^^^^^^^^^^^^^^^^^^^^^^^^^^^^
django.db.utils.IntegrityError: duplicate key value violates unique constraint "accounts_user_email_key"
DETAIL:  Key (email)=() already exists.

"POST /api/auth/anonymous/ HTTP/1.1" 500 216700
Internal Server Error: /api/auth/anonymous/
Traceback (most recent call last):
  File "C:\Users\ansh0\Desktop\Python\MindSpace\backend\venv\Lib\site-packages\django\db\backends\utils.py", line 105, in _execute
    return self.cursor.execute(sql, params)
           ^^^^^^^^^^^^^^^^^^^^^^^^^^^^^^^^
psycopg2.errors.UniqueViolation: duplicate key value violates unique constraint "accounts_user_email_key"
DETAIL:  Key (email)=() already exists.


The above exception was the direct cause of the following exception:

Traceback (most recent call last):
  File "C:\Users\ansh0\Desktop\Python\MindSpace\backend\venv\Lib\site-packages\django\core\handlers\exception.py", line 55, in inner
    response = get_response(request)
               ^^^^^^^^^^^^^^^^^^^^^
  File "C:\Users\ansh0\Desktop\Python\MindSpace\backend\venv\Lib\site-packages\django\core\handlers\base.py", line 197, in _get_response
    response = wrapped_callback(request, *callback_args, **callback_kwargs)
               ^^^^^^^^^^^^^^^^^^^^^^^^^^^^^^^^^^^^^^^^^^^^^^^^^^^^^^^^^^^^
  File "C:\Users\ansh0\Desktop\Python\MindSpace\backend\venv\Lib\site-packages\django\views\decorators\csrf.py", line 65, in _view_wrapper
    return view_func(request, *args, **kwargs)
           ^^^^^^^^^^^^^^^^^^^^^^^^^^^^^^^^^^^
  File "C:\Users\ansh0\Desktop\Python\MindSpace\backend\venv\Lib\site-packages\django\views\generic\base.py", line 105, in view
    return self.dispatch(request, *args, **kwargs)
           ^^^^^^^^^^^^^^^^^^^^^^^^^^^^^^^^^^^^^^^
  File "C:\Users\ansh0\Desktop\Python\MindSpace\backend\venv\Lib\site-packages\rest_framework\views.py", line 515, in dispatch
    response = self.handle_exception(exc)
               ^^^^^^^^^^^^^^^^^^^^^^^^^^
  File "C:\Users\ansh0\Desktop\Python\MindSpace\backend\venv\Lib\site-packages\rest_framework\views.py", line 475, in handle_exception
    self.raise_uncaught_exception(exc)
  File "C:\Users\ansh0\Desktop\Python\MindSpace\backend\venv\Lib\site-packages\rest_framework\views.py", line 486, in raise_uncaught_exception
    raise exc
  File "C:\Users\ansh0\Desktop\Python\MindSpace\backend\venv\Lib\site-packages\rest_framework\views.py", line 512, in dispatch
    response = handler(request, *args, **kwargs)
               ^^^^^^^^^^^^^^^^^^^^^^^^^^^^^^^^^
  File "C:\Users\ansh0\Desktop\Python\MindSpace\backend\venv\Lib\site-packages\rest_framework\decorators.py", line 50, in handler
    return func(*args, **kwargs)
           ^^^^^^^^^^^^^^^^^^^^^
  File "C:\Users\ansh0\Desktop\Python\MindSpace\backend\accounts\views.py", line 56, in create_anonymous_user
    user = serializer.save()
           ^^^^^^^^^^^^^^^^^
  File "C:\Users\ansh0\Desktop\Python\MindSpace\backend\venv\Lib\site-packages\rest_framework\serializers.py", line 210, in save
    self.instance = self.create(validated_data)
                    ^^^^^^^^^^^^^^^^^^^^^^^^^^^
  File "C:\Users\ansh0\Desktop\Python\MindSpace\backend\accounts\serializers.py", line 94, in create
    user = User.objects.create_user(
           ^^^^^^^^^^^^^^^^^^^^^^^^^
  File "C:\Users\ansh0\Desktop\Python\MindSpace\backend\venv\Lib\site-packages\django\contrib\auth\models.py", line 175, in create_user
    return self._create_user(username, email, password, **extra_fields)
           ^^^^^^^^^^^^^^^^^^^^^^^^^^^^^^^^^^^^^^^^^^^^^^^^^^^^^^^^^^^^
  File "C:\Users\ansh0\Desktop\Python\MindSpace\backend\venv\Lib\site-packages\django\contrib\auth\models.py", line 163, in _create_user
    user.save(using=self._db)
  File "C:\Users\ansh0\Desktop\Python\MindSpace\backend\accounts\models.py", line 65, in save
    super().save(*args, **kwargs)
  File "C:\Users\ansh0\Desktop\Python\MindSpace\backend\venv\Lib\site-packages\django\contrib\auth\base_user.py", line 65, in save
    super().save(*args, **kwargs)
  File "C:\Users\ansh0\Desktop\Python\MindSpace\backend\venv\Lib\site-packages\django\db\models\base.py", line 902, in save
    self.save_base(
  File "C:\Users\ansh0\Desktop\Python\MindSpace\backend\venv\Lib\site-packages\django\db\models\base.py", line 1008, in save_base
    updated = self._save_table(
              ^^^^^^^^^^^^^^^^^
  File "C:\Users\ansh0\Desktop\Python\MindSpace\backend\venv\Lib\site-packages\django\db\models\base.py", line 1169, in _save_table
    results = self._do_insert(
              ^^^^^^^^^^^^^^^^
  File "C:\Users\ansh0\Desktop\Python\MindSpace\backend\venv\Lib\site-packages\django\db\models\base.py", line 1210, in _do_insert
    return manager._insert(
           ^^^^^^^^^^^^^^^^
  File "C:\Users\ansh0\Desktop\Python\MindSpace\backend\venv\Lib\site-packages\django\db\models\manager.py", line 87, in manager_method
    return getattr(self.get_queryset(), name)(*args, **kwargs)
           ^^^^^^^^^^^^^^^^^^^^^^^^^^^^^^^^^^^^^^^^^^^^^^^^^^^
  File "C:\Users\ansh0\Desktop\Python\MindSpace\backend\venv\Lib\site-packages\django\db\models\query.py", line 1868, in _insert
    return query.get_compiler(using=using).execute_sql(returning_fields)
           ^^^^^^^^^^^^^^^^^^^^^^^^^^^^^^^^^^^^^^^^^^^^^^^^^^^^^^^^^^^^^
  File "C:\Users\ansh0\Desktop\Python\MindSpace\backend\venv\Lib\site-packages\django\db\models\sql\compiler.py", line 1882, in execute_sql
    cursor.execute(sql, params)
  File "C:\Users\ansh0\Desktop\Python\MindSpace\backend\venv\Lib\site-packages\django\db\backends\utils.py", line 122, in execute
    return super().execute(sql, params)
           ^^^^^^^^^^^^^^^^^^^^^^^^^^^^
  File "C:\Users\ansh0\Desktop\Python\MindSpace\backend\venv\Lib\site-packages\django\db\backends\utils.py", line 79, in execute
    return self._execute_with_wrappers(
           ^^^^^^^^^^^^^^^^^^^^^^^^^^^^
  File "C:\Users\ansh0\Desktop\Python\MindSpace\backend\venv\Lib\site-packages\django\db\backends\utils.py", line 92, in _execute_with_wrappers
    return executor(sql, params, many, context)
           ^^^^^^^^^^^^^^^^^^^^^^^^^^^^^^^^^^^^
  File "C:\Users\ansh0\Desktop\Python\MindSpace\backend\venv\Lib\site-packages\django\db\backends\utils.py", line 100, in _execute
    with self.db.wrap_database_errors:
  File "C:\Users\ansh0\Desktop\Python\MindSpace\backend\venv\Lib\site-packages\django\db\utils.py", line 91, in __exit__
    raise dj_exc_value.with_traceback(traceback) from exc_value
  File "C:\Users\ansh0\Desktop\Python\MindSpace\backend\venv\Lib\site-packages\django\db\backends\utils.py", line 105, in _execute
    return self.cursor.execute(sql, params)
           ^^^^^^^^^^^^^^^^^^^^^^^^^^^^^^^^
django.db.utils.IntegrityError: duplicate key value violates unique constraint "accounts_user_email_key"
DETAIL:  Key (email)=() already exists.

"POST /api/auth/anonymous/ HTTP/1.1" 500 216705
"OPTIONS /api/auth/login/ HTTP/1.1" 200 0
Bad Request: /api/auth/login/
"POST /api/auth/login/ HTTP/1.1" 400 44
"OPTIONS /api/auth/register/ HTTP/1.1" 200 0
Bad Request: /api/auth/register/
"POST /api/auth/register/ HTTP/1.1" 400 50
Bad Request: /api/auth/register/
"POST /api/auth/register/ HTTP/1.1" 400 50
Bad Request: /api/auth/register/
"POST /api/auth/register/ HTTP/1.1" 400 50
Bad Request: /api/auth/login/
"POST /api/auth/login/ HTTP/1.1" 400 44
Watching for file changes with StatReloader
"HEAD /admin/ HTTP/1.1" 302 0
"HEAD /admin/ HTTP/1.1" 302 0
"HEAD /admin/login/?next=/admin/ HTTP/1.1" 200 0
"HEAD /admin/login/?next=/admin/ HTTP/1.1" 200 0
Watching for file changes with StatReloader
"HEAD /admin/ HTTP/1.1" 302 0
"HEAD /admin/ HTTP/1.1" 302 0
"HEAD /admin/login/?next=/admin/ HTTP/1.1" 200 0
"HEAD /admin/login/?next=/admin/ HTTP/1.1" 200 0
Watching for file changes with StatReloader
"HEAD /admin/ HTTP/1.1" 302 0
"HEAD /admin/ HTTP/1.1" 302 0
"HEAD /admin/login/?next=/admin/ HTTP/1.1" 200 0
"HEAD /admin/login/?next=/admin/ HTTP/1.1" 200 0
